[2025-02-02T19:59:23.096+0000] {local_task_job_runner.py:123} INFO - ::group::Pre task execution logs
[2025-02-02T19:59:23.110+0000] {taskinstance.py:2603} INFO - Dependencies all met for dep_context=non-requeueable deps ti=<TaskInstance: flights_pipeline.load_data_into_duckdb manual__2025-02-02T19:54:00.616192+00:00 [queued]>
[2025-02-02T19:59:23.118+0000] {taskinstance.py:2603} INFO - Dependencies all met for dep_context=requeueable deps ti=<TaskInstance: flights_pipeline.load_data_into_duckdb manual__2025-02-02T19:54:00.616192+00:00 [queued]>
[2025-02-02T19:59:23.120+0000] {taskinstance.py:2856} INFO - Starting attempt 2 of 2
[2025-02-02T19:59:23.131+0000] {taskinstance.py:2879} INFO - Executing <Task(_PythonDecoratedOperator): load_data_into_duckdb> on 2025-02-02 19:54:00.616192+00:00
[2025-02-02T19:59:23.153+0000] {warnings.py:112} WARNING - /home/***/.local/lib/python3.12/site-packages/***/task/task_runner/standard_task_runner.py:70: DeprecationWarning: This process (pid=2546) is multi-threaded, use of fork() may lead to deadlocks in the child.
  pid = os.fork()

[2025-02-02T19:59:23.154+0000] {standard_task_runner.py:104} INFO - Running: ['***', 'tasks', 'run', 'flights_pipeline', 'load_data_into_duckdb', 'manual__2025-02-02T19:54:00.616192+00:00', '--job-id', '62', '--raw', '--subdir', 'DAGS_FOLDER/zdag.py', '--cfg-path', '/tmp/tmpn8j383w6']
[2025-02-02T19:59:23.163+0000] {standard_task_runner.py:72} INFO - Started process 2578 to run task
[2025-02-02T19:59:23.163+0000] {standard_task_runner.py:105} INFO - Job 62: Subtask load_data_into_duckdb
[2025-02-02T19:59:23.212+0000] {task_command.py:467} INFO - Running <TaskInstance: flights_pipeline.load_data_into_duckdb manual__2025-02-02T19:54:00.616192+00:00 [running]> on host d628bd12729b
[2025-02-02T19:59:23.259+0000] {taskinstance.py:3122} INFO - Exporting env vars: AIRFLOW_CTX_DAG_OWNER='***' AIRFLOW_CTX_DAG_ID='flights_pipeline' AIRFLOW_CTX_TASK_ID='load_data_into_duckdb' AIRFLOW_CTX_EXECUTION_DATE='2025-02-02T19:54:00.616192+00:00' AIRFLOW_CTX_TRY_NUMBER='2' AIRFLOW_CTX_DAG_RUN_ID='manual__2025-02-02T19:54:00.616192+00:00'
[2025-02-02T19:59:23.260+0000] {taskinstance.py:731} INFO - ::endgroup::
[2025-02-02T19:59:23.814+0000] {logging_mixin.py:190} INFO - Ligne ignorée (time_position manquant): {'icao24': 'a5a8b5', 'callsign': '', 'origin_country': 'United States', 'time_position': None, 'last_contact': 1738525859, 'longitude': None, 'latitude': None, 'baro_altitude': None, 'on_ground': False, 'velocity': 51.14, 'true_track': 174.81, 'vertical_rate': 0.33, 'sensors': None, 'geo_altitude': None, 'squawk': None, 'spi': False, 'position_source': 0, 'category': 0}
[2025-02-02T19:59:23.930+0000] {logging_mixin.py:190} INFO - Ligne ignorée (time_position manquant): {'icao24': 'e0b244', 'callsign': 'ARG1246 ', 'origin_country': 'Argentina', 'time_position': None, 'last_contact': 1738526031, 'longitude': None, 'latitude': None, 'baro_altitude': None, 'on_ground': False, 'velocity': 229.83, 'true_track': 30.99, 'vertical_rate': 0, 'sensors': None, 'geo_altitude': None, 'squawk': None, 'spi': False, 'position_source': 0, 'category': 0}
[2025-02-02T19:59:23.940+0000] {logging_mixin.py:190} INFO - Ligne ignorée (time_position manquant): {'icao24': 'c81d8e', 'callsign': '', 'origin_country': 'New Zealand', 'time_position': None, 'last_contact': 1738526030, 'longitude': None, 'latitude': None, 'baro_altitude': None, 'on_ground': False, 'velocity': 213.36, 'true_track': 204.96, 'vertical_rate': 0, 'sensors': None, 'geo_altitude': None, 'squawk': None, 'spi': False, 'position_source': 0, 'category': 0}
[2025-02-02T19:59:23.997+0000] {logging_mixin.py:190} INFO - Ligne ignorée (time_position manquant): {'icao24': 'e4803d', 'callsign': 'TAM8143 ', 'origin_country': 'Brazil', 'time_position': None, 'last_contact': 1738525783, 'longitude': None, 'latitude': None, 'baro_altitude': None, 'on_ground': False, 'velocity': 226.41, 'true_track': 39.01, 'vertical_rate': 0, 'sensors': None, 'geo_altitude': None, 'squawk': None, 'spi': False, 'position_source': 0, 'category': 0}
[2025-02-02T19:59:24.043+0000] {logging_mixin.py:190} INFO - Ligne ignorée (time_position manquant): {'icao24': 'a283af', 'callsign': '', 'origin_country': 'United States', 'time_position': None, 'last_contact': 1738525728, 'longitude': None, 'latitude': None, 'baro_altitude': None, 'on_ground': False, 'velocity': 67.91, 'true_track': 0.87, 'vertical_rate': 0.33, 'sensors': None, 'geo_altitude': None, 'squawk': None, 'spi': False, 'position_source': 0, 'category': 0}
[2025-02-02T19:59:24.044+0000] {logging_mixin.py:190} INFO - Ligne ignorée (time_position manquant): {'icao24': 'a2dfbc', 'callsign': 'N2844A  ', 'origin_country': 'United States', 'time_position': None, 'last_contact': 1738525798, 'longitude': None, 'latitude': None, 'baro_altitude': None, 'on_ground': False, 'velocity': 52.48, 'true_track': 269.44, 'vertical_rate': 0.65, 'sensors': None, 'geo_altitude': None, 'squawk': None, 'spi': False, 'position_source': 0, 'category': 0}
[2025-02-02T19:59:24.098+0000] {logging_mixin.py:190} INFO - Ligne ignorée (time_position manquant): {'icao24': 'a70002', 'callsign': 'N550GA  ', 'origin_country': 'United States', 'time_position': None, 'last_contact': 1738526018, 'longitude': None, 'latitude': None, 'baro_altitude': None, 'on_ground': False, 'velocity': 0, 'true_track': 0, 'vertical_rate': 0, 'sensors': None, 'geo_altitude': None, 'squawk': None, 'spi': False, 'position_source': 0, 'category': 0}
[2025-02-02T19:59:24.113+0000] {logging_mixin.py:190} INFO - Ligne ignorée (time_position manquant): {'icao24': 'ad442d', 'callsign': 'N954GV  ', 'origin_country': 'United States', 'time_position': None, 'last_contact': 1738526031, 'longitude': None, 'latitude': None, 'baro_altitude': None, 'on_ground': False, 'velocity': 64.77, 'true_track': 136.29, 'vertical_rate': 1.3, 'sensors': None, 'geo_altitude': None, 'squawk': None, 'spi': False, 'position_source': 0, 'category': 0}
[2025-02-02T19:59:24.115+0000] {logging_mixin.py:190} INFO - Ligne ignorée (time_position manquant): {'icao24': 'a6ff08', 'callsign': 'N55WB   ', 'origin_country': 'United States', 'time_position': None, 'last_contact': 1738526028, 'longitude': None, 'latitude': None, 'baro_altitude': None, 'on_ground': False, 'velocity': 56.77, 'true_track': 255.84, 'vertical_rate': -1.63, 'sensors': None, 'geo_altitude': None, 'squawk': None, 'spi': False, 'position_source': 0, 'category': 0}
[2025-02-02T19:59:24.128+0000] {logging_mixin.py:190} INFO - Ligne ignorée (time_position manquant): {'icao24': 'a6193b', 'callsign': 'WUP492  ', 'origin_country': 'United States', 'time_position': None, 'last_contact': 1738526028, 'longitude': None, 'latitude': None, 'baro_altitude': None, 'on_ground': False, 'velocity': 128.51, 'true_track': 265.41, 'vertical_rate': 10.73, 'sensors': None, 'geo_altitude': None, 'squawk': None, 'spi': False, 'position_source': 0, 'category': 0}
[2025-02-02T19:59:24.145+0000] {logging_mixin.py:190} INFO - Ligne ignorée (time_position manquant): {'icao24': 'a008c5', 'callsign': '', 'origin_country': 'United States', 'time_position': None, 'last_contact': 1738526019, 'longitude': None, 'latitude': None, 'baro_altitude': None, 'on_ground': False, 'velocity': 239.48, 'true_track': 7.03, 'vertical_rate': 0, 'sensors': None, 'geo_altitude': None, 'squawk': None, 'spi': False, 'position_source': 0, 'category': 0}
[2025-02-02T19:59:24.320+0000] {logging_mixin.py:190} INFO - Doublon ignoré: {'icao24': '702066', 'callsign': '', 'origin_country': 'Bangladesh', 'time_position': 1738526031, 'last_contact': 1738526031, 'longitude': 99.9363, 'latitude': 8.8755, 'baro_altitude': 10972.8, 'on_ground': False, 'velocity': 246.21, 'true_track': 351.23, 'vertical_rate': 0, 'sensors': None, 'geo_altitude': 11643.36, 'squawk': None, 'spi': False, 'position_source': 0, 'category': 0} - Erreur: Constraint Error: PRIMARY KEY or UNIQUE constraint violated: duplicate key ", 1738526031, 1738526031"
[2025-02-02T19:59:24.322+0000] {logging_mixin.py:190} INFO - Doublon ignoré: {'icao24': '4b15ed', 'callsign': 'SWR259T ', 'origin_country': 'Switzerland', 'time_position': 1738526029, 'last_contact': 1738526029, 'longitude': 11.7598, 'latitude': 42.8697, 'baro_altitude': 8526.78, 'on_ground': False, 'velocity': 207.8, 'true_track': 338.96, 'vertical_rate': 4.55, 'sensors': None, 'geo_altitude': 8542.02, 'squawk': '1000', 'spi': False, 'position_source': 0, 'category': 0} - Erreur: Constraint Error: Duplicate key "callsign: SWR259T , time_position: 1738526029, last_contact: 1738526029" violates primary key constraint. If this is an unexpected constraint violation please double check with the known index limitations section in our documentation (https://duckdb.org/docs/sql/indexes).
[2025-02-02T19:59:24.327+0000] {taskinstance.py:3301} ERROR - Task failed with exception
Traceback (most recent call last):
  File "/opt/airflow/dags/zdag.py", line 98, in load_data_into_duckdb
    insert_data(conn, validated_row, colonne_open_sky)
  File "/opt/airflow/dags/zdag.py", line 155, in insert_data
    conn.execute(f"INSERT INTO openskynetwork_brute VALUES ({placeholders})", tuple(values))
duckdb.duckdb.ConstraintException: Constraint Error: Duplicate key "callsign: SWR259T , time_position: 1738526029, last_contact: 1738526029" violates primary key constraint. If this is an unexpected constraint violation please double check with the known index limitations section in our documentation (https://duckdb.org/docs/sql/indexes).

During handling of the above exception, another exception occurred:

Traceback (most recent call last):
  File "/opt/airflow/dags/zdag.py", line 101, in load_data_into_duckdb
    conn.rollback()
duckdb.duckdb.TransactionException: TransactionContext Error: cannot rollback - no transaction is active

During handling of the above exception, another exception occurred:

Traceback (most recent call last):
  File "/home/airflow/.local/lib/python3.12/site-packages/airflow/models/taskinstance.py", line 767, in _execute_task
    result = _execute_callable(context=context, **execute_callable_kwargs)
             ^^^^^^^^^^^^^^^^^^^^^^^^^^^^^^^^^^^^^^^^^^^^^^^^^^^^^^^^^^^^^
  File "/home/airflow/.local/lib/python3.12/site-packages/airflow/models/taskinstance.py", line 733, in _execute_callable
    return ExecutionCallableRunner(
           ^^^^^^^^^^^^^^^^^^^^^^^^
  File "/home/airflow/.local/lib/python3.12/site-packages/airflow/utils/operator_helpers.py", line 252, in run
    return self.func(*args, **kwargs)
           ^^^^^^^^^^^^^^^^^^^^^^^^^^
  File "/home/airflow/.local/lib/python3.12/site-packages/airflow/models/baseoperator.py", line 406, in wrapper
    return func(self, *args, **kwargs)
           ^^^^^^^^^^^^^^^^^^^^^^^^^^^
  File "/home/airflow/.local/lib/python3.12/site-packages/airflow/decorators/base.py", line 266, in execute
    return_value = super().execute(context)
                   ^^^^^^^^^^^^^^^^^^^^^^^^
  File "/home/airflow/.local/lib/python3.12/site-packages/airflow/models/baseoperator.py", line 406, in wrapper
    return func(self, *args, **kwargs)
           ^^^^^^^^^^^^^^^^^^^^^^^^^^^
  File "/home/airflow/.local/lib/python3.12/site-packages/airflow/operators/python.py", line 238, in execute
    return_value = self.execute_callable()
                   ^^^^^^^^^^^^^^^^^^^^^^^
  File "/home/airflow/.local/lib/python3.12/site-packages/airflow/operators/python.py", line 256, in execute_callable
    return runner.run(*self.op_args, **self.op_kwargs)
           ^^^^^^^^^^^^^^^^^^^^^^^^^^^^^^^^^^^^^^^^^^^
  File "/home/airflow/.local/lib/python3.12/site-packages/airflow/utils/operator_helpers.py", line 252, in run
    return self.func(*args, **kwargs)
           ^^^^^^^^^^^^^^^^^^^^^^^^^^
  File "/opt/airflow/dags/zdag.py", line 112, in load_data_into_duckdb
    conn.rollback()
duckdb.duckdb.TransactionException: TransactionContext Error: cannot rollback - no transaction is active
[2025-02-02T19:59:24.340+0000] {taskinstance.py:1225} INFO - Marking task as FAILED. dag_id=flights_pipeline, task_id=load_data_into_duckdb, run_id=manual__2025-02-02T19:54:00.616192+00:00, execution_date=20250202T195400, start_date=20250202T195923, end_date=20250202T195924
[2025-02-02T19:59:24.347+0000] {taskinstance.py:340} INFO - ::group::Post task execution logs
[2025-02-02T19:59:24.351+0000] {standard_task_runner.py:124} ERROR - Failed to execute job 62 for task load_data_into_duckdb (TransactionContext Error: cannot rollback - no transaction is active; 2578)
Traceback (most recent call last):
  File "/opt/airflow/dags/zdag.py", line 98, in load_data_into_duckdb
    insert_data(conn, validated_row, colonne_open_sky)
  File "/opt/airflow/dags/zdag.py", line 155, in insert_data
    conn.execute(f"INSERT INTO openskynetwork_brute VALUES ({placeholders})", tuple(values))
duckdb.duckdb.ConstraintException: Constraint Error: Duplicate key "callsign: SWR259T , time_position: 1738526029, last_contact: 1738526029" violates primary key constraint. If this is an unexpected constraint violation please double check with the known index limitations section in our documentation (https://duckdb.org/docs/sql/indexes).

During handling of the above exception, another exception occurred:

Traceback (most recent call last):
  File "/opt/airflow/dags/zdag.py", line 101, in load_data_into_duckdb
    conn.rollback()
duckdb.duckdb.TransactionException: TransactionContext Error: cannot rollback - no transaction is active

During handling of the above exception, another exception occurred:

Traceback (most recent call last):
  File "/home/airflow/.local/lib/python3.12/site-packages/airflow/task/task_runner/standard_task_runner.py", line 117, in _start_by_fork
    ret = args.func(args, dag=self.dag)
          ^^^^^^^^^^^^^^^^^^^^^^^^^^^^^
  File "/home/airflow/.local/lib/python3.12/site-packages/airflow/cli/cli_config.py", line 49, in command
    return func(*args, **kwargs)
           ^^^^^^^^^^^^^^^^^^^^^
  File "/home/airflow/.local/lib/python3.12/site-packages/airflow/utils/cli.py", line 115, in wrapper
    return f(*args, **kwargs)
           ^^^^^^^^^^^^^^^^^^
  File "/home/airflow/.local/lib/python3.12/site-packages/airflow/cli/commands/task_command.py", line 483, in task_run
    task_return_code = _run_task_by_selected_method(args, _dag, ti)
                       ^^^^^^^^^^^^^^^^^^^^^^^^^^^^^^^^^^^^^^^^^^^^
  File "/home/airflow/.local/lib/python3.12/site-packages/airflow/cli/commands/task_command.py", line 256, in _run_task_by_selected_method
    return _run_raw_task(args, ti)
           ^^^^^^^^^^^^^^^^^^^^^^^
  File "/home/airflow/.local/lib/python3.12/site-packages/airflow/cli/commands/task_command.py", line 341, in _run_raw_task
    return ti._run_raw_task(
           ^^^^^^^^^^^^^^^^^
  File "/home/airflow/.local/lib/python3.12/site-packages/airflow/utils/session.py", line 97, in wrapper
    return func(*args, session=session, **kwargs)
           ^^^^^^^^^^^^^^^^^^^^^^^^^^^^^^^^^^^^^^
  File "/home/airflow/.local/lib/python3.12/site-packages/airflow/models/taskinstance.py", line 2995, in _run_raw_task
    return _run_raw_task(
           ^^^^^^^^^^^^^^
  File "/home/airflow/.local/lib/python3.12/site-packages/airflow/models/taskinstance.py", line 273, in _run_raw_task
    TaskInstance._execute_task_with_callbacks(
  File "/home/airflow/.local/lib/python3.12/site-packages/airflow/models/taskinstance.py", line 3149, in _execute_task_with_callbacks
    result = self._execute_task(context, task_orig)
             ^^^^^^^^^^^^^^^^^^^^^^^^^^^^^^^^^^^^^^
  File "/home/airflow/.local/lib/python3.12/site-packages/airflow/models/taskinstance.py", line 3173, in _execute_task
    return _execute_task(self, context, task_orig)
           ^^^^^^^^^^^^^^^^^^^^^^^^^^^^^^^^^^^^^^^
  File "/home/airflow/.local/lib/python3.12/site-packages/airflow/models/taskinstance.py", line 767, in _execute_task
    result = _execute_callable(context=context, **execute_callable_kwargs)
             ^^^^^^^^^^^^^^^^^^^^^^^^^^^^^^^^^^^^^^^^^^^^^^^^^^^^^^^^^^^^^
  File "/home/airflow/.local/lib/python3.12/site-packages/airflow/models/taskinstance.py", line 733, in _execute_callable
    return ExecutionCallableRunner(
           ^^^^^^^^^^^^^^^^^^^^^^^^
  File "/home/airflow/.local/lib/python3.12/site-packages/airflow/utils/operator_helpers.py", line 252, in run
    return self.func(*args, **kwargs)
           ^^^^^^^^^^^^^^^^^^^^^^^^^^
  File "/home/airflow/.local/lib/python3.12/site-packages/airflow/models/baseoperator.py", line 406, in wrapper
    return func(self, *args, **kwargs)
           ^^^^^^^^^^^^^^^^^^^^^^^^^^^
  File "/home/airflow/.local/lib/python3.12/site-packages/airflow/decorators/base.py", line 266, in execute
    return_value = super().execute(context)
                   ^^^^^^^^^^^^^^^^^^^^^^^^
  File "/home/airflow/.local/lib/python3.12/site-packages/airflow/models/baseoperator.py", line 406, in wrapper
    return func(self, *args, **kwargs)
           ^^^^^^^^^^^^^^^^^^^^^^^^^^^
  File "/home/airflow/.local/lib/python3.12/site-packages/airflow/operators/python.py", line 238, in execute
    return_value = self.execute_callable()
                   ^^^^^^^^^^^^^^^^^^^^^^^
  File "/home/airflow/.local/lib/python3.12/site-packages/airflow/operators/python.py", line 256, in execute_callable
    return runner.run(*self.op_args, **self.op_kwargs)
           ^^^^^^^^^^^^^^^^^^^^^^^^^^^^^^^^^^^^^^^^^^^
  File "/home/airflow/.local/lib/python3.12/site-packages/airflow/utils/operator_helpers.py", line 252, in run
    return self.func(*args, **kwargs)
           ^^^^^^^^^^^^^^^^^^^^^^^^^^
  File "/opt/airflow/dags/zdag.py", line 112, in load_data_into_duckdb
    conn.rollback()
duckdb.duckdb.TransactionException: TransactionContext Error: cannot rollback - no transaction is active
[2025-02-02T19:59:24.381+0000] {local_task_job_runner.py:261} INFO - Task exited with return code 1
[2025-02-02T19:59:24.396+0000] {taskinstance.py:3891} INFO - 0 downstream tasks scheduled from follow-on schedule check
[2025-02-02T19:59:24.401+0000] {local_task_job_runner.py:240} INFO - ::endgroup::
