[2025-02-02T16:20:42.999+0000] {local_task_job_runner.py:123} INFO - ::group::Pre task execution logs
[2025-02-02T16:20:43.010+0000] {taskinstance.py:2603} INFO - Dependencies all met for dep_context=non-requeueable deps ti=<TaskInstance: flights_pipeline.load_data_fly manual__2025-02-02T16:20:39.425879+00:00 [queued]>
[2025-02-02T16:20:43.015+0000] {taskinstance.py:2603} INFO - Dependencies all met for dep_context=requeueable deps ti=<TaskInstance: flights_pipeline.load_data_fly manual__2025-02-02T16:20:39.425879+00:00 [queued]>
[2025-02-02T16:20:43.015+0000] {taskinstance.py:2856} INFO - Starting attempt 1 of 1
[2025-02-02T16:20:43.026+0000] {taskinstance.py:2879} INFO - Executing <Task(_PythonDecoratedOperator): load_data_fly> on 2025-02-02 16:20:39.425879+00:00
[2025-02-02T16:20:43.031+0000] {warnings.py:112} WARNING - /home/***/.local/lib/python3.12/site-packages/***/task/task_runner/standard_task_runner.py:70: DeprecationWarning: This process (pid=603) is multi-threaded, use of fork() may lead to deadlocks in the child.
  pid = os.fork()

[2025-02-02T16:20:43.032+0000] {standard_task_runner.py:72} INFO - Started process 635 to run task
[2025-02-02T16:20:43.032+0000] {standard_task_runner.py:104} INFO - Running: ['***', 'tasks', 'run', 'flights_pipeline', 'load_data_fly', 'manual__2025-02-02T16:20:39.425879+00:00', '--job-id', '22', '--raw', '--subdir', 'DAGS_FOLDER/zdag.py', '--cfg-path', '/tmp/tmpy6lhr0vz']
[2025-02-02T16:20:43.033+0000] {standard_task_runner.py:105} INFO - Job 22: Subtask load_data_fly
[2025-02-02T16:20:43.064+0000] {task_command.py:467} INFO - Running <TaskInstance: flights_pipeline.load_data_fly manual__2025-02-02T16:20:39.425879+00:00 [running]> on host d628bd12729b
[2025-02-02T16:20:43.114+0000] {taskinstance.py:3122} INFO - Exporting env vars: AIRFLOW_CTX_DAG_OWNER='***' AIRFLOW_CTX_DAG_ID='flights_pipeline' AIRFLOW_CTX_TASK_ID='load_data_fly' AIRFLOW_CTX_EXECUTION_DATE='2025-02-02T16:20:39.425879+00:00' AIRFLOW_CTX_TRY_NUMBER='1' AIRFLOW_CTX_DAG_RUN_ID='manual__2025-02-02T16:20:39.425879+00:00'
[2025-02-02T16:20:43.115+0000] {taskinstance.py:731} INFO - ::endgroup::
[2025-02-02T16:20:43.117+0000] {logging_mixin.py:190} INFO - ######################################## 1
[2025-02-02T16:20:43.118+0000] {logging_mixin.py:190} INFO - ######################################## 2
[2025-02-02T16:20:43.127+0000] {logging_mixin.py:190} INFO - ######################################## 5
[2025-02-02T16:20:43.128+0000] {logging_mixin.py:190} INFO - Erreur lors du chargement des donn√©es : IO Error: Cannot open file "/opt/***/dags/data/db_test": Permission denied
[2025-02-02T16:20:43.129+0000] {logging_mixin.py:190} INFO - ######################################## 6
[2025-02-02T16:20:43.129+0000] {taskinstance.py:3301} ERROR - Task failed with exception
Traceback (most recent call last):
  File "/opt/airflow/dags/zdag.py", line 52, in load_data_fly
    conn = duckdb.connect(db_path)
           ^^^^^^^^^^^^^^^^^^^^^^^
duckdb.duckdb.IOException: IO Error: Cannot open file "/opt/***/dags/data/db_test": Permission denied

During handling of the above exception, another exception occurred:

Traceback (most recent call last):
  File "/home/airflow/.local/lib/python3.12/site-packages/airflow/models/taskinstance.py", line 767, in _execute_task
    result = _execute_callable(context=context, **execute_callable_kwargs)
             ^^^^^^^^^^^^^^^^^^^^^^^^^^^^^^^^^^^^^^^^^^^^^^^^^^^^^^^^^^^^^
  File "/home/airflow/.local/lib/python3.12/site-packages/airflow/models/taskinstance.py", line 733, in _execute_callable
    return ExecutionCallableRunner(
           ^^^^^^^^^^^^^^^^^^^^^^^^
  File "/home/airflow/.local/lib/python3.12/site-packages/airflow/utils/operator_helpers.py", line 252, in run
    return self.func(*args, **kwargs)
           ^^^^^^^^^^^^^^^^^^^^^^^^^^
  File "/home/airflow/.local/lib/python3.12/site-packages/airflow/models/baseoperator.py", line 406, in wrapper
    return func(self, *args, **kwargs)
           ^^^^^^^^^^^^^^^^^^^^^^^^^^^
  File "/home/airflow/.local/lib/python3.12/site-packages/airflow/decorators/base.py", line 266, in execute
    return_value = super().execute(context)
                   ^^^^^^^^^^^^^^^^^^^^^^^^
  File "/home/airflow/.local/lib/python3.12/site-packages/airflow/models/baseoperator.py", line 406, in wrapper
    return func(self, *args, **kwargs)
           ^^^^^^^^^^^^^^^^^^^^^^^^^^^
  File "/home/airflow/.local/lib/python3.12/site-packages/airflow/operators/python.py", line 238, in execute
    return_value = self.execute_callable()
                   ^^^^^^^^^^^^^^^^^^^^^^^
  File "/home/airflow/.local/lib/python3.12/site-packages/airflow/operators/python.py", line 256, in execute_callable
    return runner.run(*self.op_args, **self.op_kwargs)
           ^^^^^^^^^^^^^^^^^^^^^^^^^^^^^^^^^^^^^^^^^^^
  File "/home/airflow/.local/lib/python3.12/site-packages/airflow/utils/operator_helpers.py", line 252, in run
    return self.func(*args, **kwargs)
           ^^^^^^^^^^^^^^^^^^^^^^^^^^
  File "/opt/airflow/dags/zdag.py", line 62, in load_data_fly
    if conn:
       ^^^^
UnboundLocalError: cannot access local variable 'conn' where it is not associated with a value
[2025-02-02T16:20:43.145+0000] {taskinstance.py:1225} INFO - Marking task as FAILED. dag_id=flights_pipeline, task_id=load_data_fly, run_id=manual__2025-02-02T16:20:39.425879+00:00, execution_date=20250202T162039, start_date=20250202T162043, end_date=20250202T162043
[2025-02-02T16:20:43.155+0000] {taskinstance.py:340} INFO - ::group::Post task execution logs
[2025-02-02T16:20:43.155+0000] {standard_task_runner.py:124} ERROR - Failed to execute job 22 for task load_data_fly (cannot access local variable 'conn' where it is not associated with a value; 635)
Traceback (most recent call last):
  File "/opt/airflow/dags/zdag.py", line 52, in load_data_fly
    conn = duckdb.connect(db_path)
           ^^^^^^^^^^^^^^^^^^^^^^^
duckdb.duckdb.IOException: IO Error: Cannot open file "/opt/***/dags/data/db_test": Permission denied

During handling of the above exception, another exception occurred:

Traceback (most recent call last):
  File "/home/airflow/.local/lib/python3.12/site-packages/airflow/task/task_runner/standard_task_runner.py", line 117, in _start_by_fork
    ret = args.func(args, dag=self.dag)
          ^^^^^^^^^^^^^^^^^^^^^^^^^^^^^
  File "/home/airflow/.local/lib/python3.12/site-packages/airflow/cli/cli_config.py", line 49, in command
    return func(*args, **kwargs)
           ^^^^^^^^^^^^^^^^^^^^^
  File "/home/airflow/.local/lib/python3.12/site-packages/airflow/utils/cli.py", line 115, in wrapper
    return f(*args, **kwargs)
           ^^^^^^^^^^^^^^^^^^
  File "/home/airflow/.local/lib/python3.12/site-packages/airflow/cli/commands/task_command.py", line 483, in task_run
    task_return_code = _run_task_by_selected_method(args, _dag, ti)
                       ^^^^^^^^^^^^^^^^^^^^^^^^^^^^^^^^^^^^^^^^^^^^
  File "/home/airflow/.local/lib/python3.12/site-packages/airflow/cli/commands/task_command.py", line 256, in _run_task_by_selected_method
    return _run_raw_task(args, ti)
           ^^^^^^^^^^^^^^^^^^^^^^^
  File "/home/airflow/.local/lib/python3.12/site-packages/airflow/cli/commands/task_command.py", line 341, in _run_raw_task
    return ti._run_raw_task(
           ^^^^^^^^^^^^^^^^^
  File "/home/airflow/.local/lib/python3.12/site-packages/airflow/utils/session.py", line 97, in wrapper
    return func(*args, session=session, **kwargs)
           ^^^^^^^^^^^^^^^^^^^^^^^^^^^^^^^^^^^^^^
  File "/home/airflow/.local/lib/python3.12/site-packages/airflow/models/taskinstance.py", line 2995, in _run_raw_task
    return _run_raw_task(
           ^^^^^^^^^^^^^^
  File "/home/airflow/.local/lib/python3.12/site-packages/airflow/models/taskinstance.py", line 273, in _run_raw_task
    TaskInstance._execute_task_with_callbacks(
  File "/home/airflow/.local/lib/python3.12/site-packages/airflow/models/taskinstance.py", line 3149, in _execute_task_with_callbacks
    result = self._execute_task(context, task_orig)
             ^^^^^^^^^^^^^^^^^^^^^^^^^^^^^^^^^^^^^^
  File "/home/airflow/.local/lib/python3.12/site-packages/airflow/models/taskinstance.py", line 3173, in _execute_task
    return _execute_task(self, context, task_orig)
           ^^^^^^^^^^^^^^^^^^^^^^^^^^^^^^^^^^^^^^^
  File "/home/airflow/.local/lib/python3.12/site-packages/airflow/models/taskinstance.py", line 767, in _execute_task
    result = _execute_callable(context=context, **execute_callable_kwargs)
             ^^^^^^^^^^^^^^^^^^^^^^^^^^^^^^^^^^^^^^^^^^^^^^^^^^^^^^^^^^^^^
  File "/home/airflow/.local/lib/python3.12/site-packages/airflow/models/taskinstance.py", line 733, in _execute_callable
    return ExecutionCallableRunner(
           ^^^^^^^^^^^^^^^^^^^^^^^^
  File "/home/airflow/.local/lib/python3.12/site-packages/airflow/utils/operator_helpers.py", line 252, in run
    return self.func(*args, **kwargs)
           ^^^^^^^^^^^^^^^^^^^^^^^^^^
  File "/home/airflow/.local/lib/python3.12/site-packages/airflow/models/baseoperator.py", line 406, in wrapper
    return func(self, *args, **kwargs)
           ^^^^^^^^^^^^^^^^^^^^^^^^^^^
  File "/home/airflow/.local/lib/python3.12/site-packages/airflow/decorators/base.py", line 266, in execute
    return_value = super().execute(context)
                   ^^^^^^^^^^^^^^^^^^^^^^^^
  File "/home/airflow/.local/lib/python3.12/site-packages/airflow/models/baseoperator.py", line 406, in wrapper
    return func(self, *args, **kwargs)
           ^^^^^^^^^^^^^^^^^^^^^^^^^^^
  File "/home/airflow/.local/lib/python3.12/site-packages/airflow/operators/python.py", line 238, in execute
    return_value = self.execute_callable()
                   ^^^^^^^^^^^^^^^^^^^^^^^
  File "/home/airflow/.local/lib/python3.12/site-packages/airflow/operators/python.py", line 256, in execute_callable
    return runner.run(*self.op_args, **self.op_kwargs)
           ^^^^^^^^^^^^^^^^^^^^^^^^^^^^^^^^^^^^^^^^^^^
  File "/home/airflow/.local/lib/python3.12/site-packages/airflow/utils/operator_helpers.py", line 252, in run
    return self.func(*args, **kwargs)
           ^^^^^^^^^^^^^^^^^^^^^^^^^^
  File "/opt/airflow/dags/zdag.py", line 62, in load_data_fly
    if conn:
       ^^^^
UnboundLocalError: cannot access local variable 'conn' where it is not associated with a value
[2025-02-02T16:20:43.166+0000] {local_task_job_runner.py:261} INFO - Task exited with return code 1
[2025-02-02T16:20:43.178+0000] {taskinstance.py:3891} INFO - 0 downstream tasks scheduled from follow-on schedule check
[2025-02-02T16:20:43.182+0000] {local_task_job_runner.py:240} INFO - ::endgroup::
