[2025-02-02T19:27:38.880+0000] {local_task_job_runner.py:123} INFO - ::group::Pre task execution logs
[2025-02-02T19:27:38.892+0000] {taskinstance.py:2603} INFO - Dependencies all met for dep_context=non-requeueable deps ti=<TaskInstance: flights_pipeline.load_data_into_duckdb manual__2025-02-02T19:22:29.558027+00:00 [queued]>
[2025-02-02T19:27:38.899+0000] {taskinstance.py:2603} INFO - Dependencies all met for dep_context=requeueable deps ti=<TaskInstance: flights_pipeline.load_data_into_duckdb manual__2025-02-02T19:22:29.558027+00:00 [queued]>
[2025-02-02T19:27:38.902+0000] {taskinstance.py:2856} INFO - Starting attempt 2 of 2
[2025-02-02T19:27:38.913+0000] {taskinstance.py:2879} INFO - Executing <Task(_PythonDecoratedOperator): load_data_into_duckdb> on 2025-02-02 19:22:29.558027+00:00
[2025-02-02T19:27:38.918+0000] {warnings.py:112} WARNING - /home/***/.local/lib/python3.12/site-packages/***/task/task_runner/standard_task_runner.py:70: DeprecationWarning: This process (pid=1705) is multi-threaded, use of fork() may lead to deadlocks in the child.
  pid = os.fork()

[2025-02-02T19:27:38.919+0000] {standard_task_runner.py:104} INFO - Running: ['***', 'tasks', 'run', 'flights_pipeline', 'load_data_into_duckdb', 'manual__2025-02-02T19:22:29.558027+00:00', '--job-id', '54', '--raw', '--subdir', 'DAGS_FOLDER/zdag.py', '--cfg-path', '/tmp/tmpuy1k16yd']
[2025-02-02T19:27:38.920+0000] {standard_task_runner.py:72} INFO - Started process 1737 to run task
[2025-02-02T19:27:38.923+0000] {standard_task_runner.py:105} INFO - Job 54: Subtask load_data_into_duckdb
[2025-02-02T19:27:38.958+0000] {task_command.py:467} INFO - Running <TaskInstance: flights_pipeline.load_data_into_duckdb manual__2025-02-02T19:22:29.558027+00:00 [running]> on host d628bd12729b
[2025-02-02T19:27:39.011+0000] {taskinstance.py:3122} INFO - Exporting env vars: AIRFLOW_CTX_DAG_OWNER='***' AIRFLOW_CTX_DAG_ID='flights_pipeline' AIRFLOW_CTX_TASK_ID='load_data_into_duckdb' AIRFLOW_CTX_EXECUTION_DATE='2025-02-02T19:22:29.558027+00:00' AIRFLOW_CTX_TRY_NUMBER='2' AIRFLOW_CTX_DAG_RUN_ID='manual__2025-02-02T19:22:29.558027+00:00'
[2025-02-02T19:27:39.012+0000] {taskinstance.py:731} INFO - ::endgroup::
[2025-02-02T19:27:39.626+0000] {logging_mixin.py:190} INFO - Doublon ignor√©: ['e49406', 'GLO7684 ', 'Brazil', 1738524144, 1738524147, -55.9243, -32.6173, 10363.2, False, 226.71, 223.44, 0, None, 10927.08, None, False, 0, 0]
[2025-02-02T19:27:39.627+0000] {logging_mixin.py:190} INFO - Error loading data into DuckDB: TransactionContext Error: cannot rollback - no transaction is active
[2025-02-02T19:27:39.638+0000] {taskinstance.py:3301} ERROR - Task failed with exception
Traceback (most recent call last):
  File "/opt/airflow/dags/zdag.py", line 97, in load_data_into_duckdb
    conn.execute(f"INSERT INTO openskynetwork_brute VALUES ({placeholders})", tuple(values))
duckdb.duckdb.ConstraintException: Constraint Error: Duplicate key "callsign: GLO7684 , time_position: 1738524144, last_contact: 1738524147" violates primary key constraint. If this is an unexpected constraint violation please double check with the known index limitations section in our documentation (https://duckdb.org/docs/sql/indexes).

During handling of the above exception, another exception occurred:

Traceback (most recent call last):
  File "/home/airflow/.local/lib/python3.12/site-packages/airflow/models/taskinstance.py", line 767, in _execute_task
    result = _execute_callable(context=context, **execute_callable_kwargs)
             ^^^^^^^^^^^^^^^^^^^^^^^^^^^^^^^^^^^^^^^^^^^^^^^^^^^^^^^^^^^^^
  File "/home/airflow/.local/lib/python3.12/site-packages/airflow/models/taskinstance.py", line 733, in _execute_callable
    return ExecutionCallableRunner(
           ^^^^^^^^^^^^^^^^^^^^^^^^
  File "/home/airflow/.local/lib/python3.12/site-packages/airflow/utils/operator_helpers.py", line 252, in run
    return self.func(*args, **kwargs)
           ^^^^^^^^^^^^^^^^^^^^^^^^^^
  File "/home/airflow/.local/lib/python3.12/site-packages/airflow/models/baseoperator.py", line 406, in wrapper
    return func(self, *args, **kwargs)
           ^^^^^^^^^^^^^^^^^^^^^^^^^^^
  File "/home/airflow/.local/lib/python3.12/site-packages/airflow/decorators/base.py", line 266, in execute
    return_value = super().execute(context)
                   ^^^^^^^^^^^^^^^^^^^^^^^^
  File "/home/airflow/.local/lib/python3.12/site-packages/airflow/models/baseoperator.py", line 406, in wrapper
    return func(self, *args, **kwargs)
           ^^^^^^^^^^^^^^^^^^^^^^^^^^^
  File "/home/airflow/.local/lib/python3.12/site-packages/airflow/operators/python.py", line 238, in execute
    return_value = self.execute_callable()
                   ^^^^^^^^^^^^^^^^^^^^^^^
  File "/home/airflow/.local/lib/python3.12/site-packages/airflow/operators/python.py", line 256, in execute_callable
    return runner.run(*self.op_args, **self.op_kwargs)
           ^^^^^^^^^^^^^^^^^^^^^^^^^^^^^^^^^^^^^^^^^^^
  File "/home/airflow/.local/lib/python3.12/site-packages/airflow/utils/operator_helpers.py", line 252, in run
    return self.func(*args, **kwargs)
           ^^^^^^^^^^^^^^^^^^^^^^^^^^
  File "/opt/airflow/dags/zdag.py", line 100, in load_data_into_duckdb
    conn.rollback() #annuler l'insertion en doublon
    ^^^^^^^^^^^^^^^
duckdb.duckdb.TransactionException: TransactionContext Error: cannot rollback - no transaction is active
[2025-02-02T19:27:39.669+0000] {taskinstance.py:1225} INFO - Marking task as FAILED. dag_id=flights_pipeline, task_id=load_data_into_duckdb, run_id=manual__2025-02-02T19:22:29.558027+00:00, execution_date=20250202T192229, start_date=20250202T192738, end_date=20250202T192739
[2025-02-02T19:27:39.678+0000] {taskinstance.py:340} INFO - ::group::Post task execution logs
[2025-02-02T19:27:39.678+0000] {standard_task_runner.py:124} ERROR - Failed to execute job 54 for task load_data_into_duckdb (TransactionContext Error: cannot rollback - no transaction is active; 1737)
Traceback (most recent call last):
  File "/opt/airflow/dags/zdag.py", line 97, in load_data_into_duckdb
    conn.execute(f"INSERT INTO openskynetwork_brute VALUES ({placeholders})", tuple(values))
duckdb.duckdb.ConstraintException: Constraint Error: Duplicate key "callsign: GLO7684 , time_position: 1738524144, last_contact: 1738524147" violates primary key constraint. If this is an unexpected constraint violation please double check with the known index limitations section in our documentation (https://duckdb.org/docs/sql/indexes).

During handling of the above exception, another exception occurred:

Traceback (most recent call last):
  File "/home/airflow/.local/lib/python3.12/site-packages/airflow/task/task_runner/standard_task_runner.py", line 117, in _start_by_fork
    ret = args.func(args, dag=self.dag)
          ^^^^^^^^^^^^^^^^^^^^^^^^^^^^^
  File "/home/airflow/.local/lib/python3.12/site-packages/airflow/cli/cli_config.py", line 49, in command
    return func(*args, **kwargs)
           ^^^^^^^^^^^^^^^^^^^^^
  File "/home/airflow/.local/lib/python3.12/site-packages/airflow/utils/cli.py", line 115, in wrapper
    return f(*args, **kwargs)
           ^^^^^^^^^^^^^^^^^^
  File "/home/airflow/.local/lib/python3.12/site-packages/airflow/cli/commands/task_command.py", line 483, in task_run
    task_return_code = _run_task_by_selected_method(args, _dag, ti)
                       ^^^^^^^^^^^^^^^^^^^^^^^^^^^^^^^^^^^^^^^^^^^^
  File "/home/airflow/.local/lib/python3.12/site-packages/airflow/cli/commands/task_command.py", line 256, in _run_task_by_selected_method
    return _run_raw_task(args, ti)
           ^^^^^^^^^^^^^^^^^^^^^^^
  File "/home/airflow/.local/lib/python3.12/site-packages/airflow/cli/commands/task_command.py", line 341, in _run_raw_task
    return ti._run_raw_task(
           ^^^^^^^^^^^^^^^^^
  File "/home/airflow/.local/lib/python3.12/site-packages/airflow/utils/session.py", line 97, in wrapper
    return func(*args, session=session, **kwargs)
           ^^^^^^^^^^^^^^^^^^^^^^^^^^^^^^^^^^^^^^
  File "/home/airflow/.local/lib/python3.12/site-packages/airflow/models/taskinstance.py", line 2995, in _run_raw_task
    return _run_raw_task(
           ^^^^^^^^^^^^^^
  File "/home/airflow/.local/lib/python3.12/site-packages/airflow/models/taskinstance.py", line 273, in _run_raw_task
    TaskInstance._execute_task_with_callbacks(
  File "/home/airflow/.local/lib/python3.12/site-packages/airflow/models/taskinstance.py", line 3149, in _execute_task_with_callbacks
    result = self._execute_task(context, task_orig)
             ^^^^^^^^^^^^^^^^^^^^^^^^^^^^^^^^^^^^^^
  File "/home/airflow/.local/lib/python3.12/site-packages/airflow/models/taskinstance.py", line 3173, in _execute_task
    return _execute_task(self, context, task_orig)
           ^^^^^^^^^^^^^^^^^^^^^^^^^^^^^^^^^^^^^^^
  File "/home/airflow/.local/lib/python3.12/site-packages/airflow/models/taskinstance.py", line 767, in _execute_task
    result = _execute_callable(context=context, **execute_callable_kwargs)
             ^^^^^^^^^^^^^^^^^^^^^^^^^^^^^^^^^^^^^^^^^^^^^^^^^^^^^^^^^^^^^
  File "/home/airflow/.local/lib/python3.12/site-packages/airflow/models/taskinstance.py", line 733, in _execute_callable
    return ExecutionCallableRunner(
           ^^^^^^^^^^^^^^^^^^^^^^^^
  File "/home/airflow/.local/lib/python3.12/site-packages/airflow/utils/operator_helpers.py", line 252, in run
    return self.func(*args, **kwargs)
           ^^^^^^^^^^^^^^^^^^^^^^^^^^
  File "/home/airflow/.local/lib/python3.12/site-packages/airflow/models/baseoperator.py", line 406, in wrapper
    return func(self, *args, **kwargs)
           ^^^^^^^^^^^^^^^^^^^^^^^^^^^
  File "/home/airflow/.local/lib/python3.12/site-packages/airflow/decorators/base.py", line 266, in execute
    return_value = super().execute(context)
                   ^^^^^^^^^^^^^^^^^^^^^^^^
  File "/home/airflow/.local/lib/python3.12/site-packages/airflow/models/baseoperator.py", line 406, in wrapper
    return func(self, *args, **kwargs)
           ^^^^^^^^^^^^^^^^^^^^^^^^^^^
  File "/home/airflow/.local/lib/python3.12/site-packages/airflow/operators/python.py", line 238, in execute
    return_value = self.execute_callable()
                   ^^^^^^^^^^^^^^^^^^^^^^^
  File "/home/airflow/.local/lib/python3.12/site-packages/airflow/operators/python.py", line 256, in execute_callable
    return runner.run(*self.op_args, **self.op_kwargs)
           ^^^^^^^^^^^^^^^^^^^^^^^^^^^^^^^^^^^^^^^^^^^
  File "/home/airflow/.local/lib/python3.12/site-packages/airflow/utils/operator_helpers.py", line 252, in run
    return self.func(*args, **kwargs)
           ^^^^^^^^^^^^^^^^^^^^^^^^^^
  File "/opt/airflow/dags/zdag.py", line 100, in load_data_into_duckdb
    conn.rollback() #annuler l'insertion en doublon
    ^^^^^^^^^^^^^^^
duckdb.duckdb.TransactionException: TransactionContext Error: cannot rollback - no transaction is active
[2025-02-02T19:27:39.699+0000] {local_task_job_runner.py:261} INFO - Task exited with return code 1
[2025-02-02T19:27:39.712+0000] {taskinstance.py:3891} INFO - 0 downstream tasks scheduled from follow-on schedule check
[2025-02-02T19:27:39.718+0000] {local_task_job_runner.py:240} INFO - ::endgroup::
