[2025-02-02T19:41:04.325+0000] {local_task_job_runner.py:123} INFO - ::group::Pre task execution logs
[2025-02-02T19:41:04.337+0000] {taskinstance.py:2603} INFO - Dependencies all met for dep_context=non-requeueable deps ti=<TaskInstance: flights_pipeline.load_data_into_duckdb manual__2025-02-02T19:35:41.450846+00:00 [queued]>
[2025-02-02T19:41:04.341+0000] {taskinstance.py:2603} INFO - Dependencies all met for dep_context=requeueable deps ti=<TaskInstance: flights_pipeline.load_data_into_duckdb manual__2025-02-02T19:35:41.450846+00:00 [queued]>
[2025-02-02T19:41:04.342+0000] {taskinstance.py:2856} INFO - Starting attempt 2 of 2
[2025-02-02T19:41:04.350+0000] {taskinstance.py:2879} INFO - Executing <Task(_PythonDecoratedOperator): load_data_into_duckdb> on 2025-02-02 19:35:41.450846+00:00
[2025-02-02T19:41:04.355+0000] {warnings.py:112} WARNING - /home/***/.local/lib/python3.12/site-packages/***/task/task_runner/standard_task_runner.py:70: DeprecationWarning: This process (pid=2100) is multi-threaded, use of fork() may lead to deadlocks in the child.
  pid = os.fork()

[2025-02-02T19:41:04.355+0000] {standard_task_runner.py:104} INFO - Running: ['***', 'tasks', 'run', 'flights_pipeline', 'load_data_into_duckdb', 'manual__2025-02-02T19:35:41.450846+00:00', '--job-id', '58', '--raw', '--subdir', 'DAGS_FOLDER/zdag.py', '--cfg-path', '/tmp/tmp6ytrqcz_']
[2025-02-02T19:41:04.356+0000] {standard_task_runner.py:72} INFO - Started process 2132 to run task
[2025-02-02T19:41:04.356+0000] {standard_task_runner.py:105} INFO - Job 58: Subtask load_data_into_duckdb
[2025-02-02T19:41:04.407+0000] {task_command.py:467} INFO - Running <TaskInstance: flights_pipeline.load_data_into_duckdb manual__2025-02-02T19:35:41.450846+00:00 [running]> on host d628bd12729b
[2025-02-02T19:41:04.468+0000] {taskinstance.py:3122} INFO - Exporting env vars: AIRFLOW_CTX_DAG_OWNER='***' AIRFLOW_CTX_DAG_ID='flights_pipeline' AIRFLOW_CTX_TASK_ID='load_data_into_duckdb' AIRFLOW_CTX_EXECUTION_DATE='2025-02-02T19:35:41.450846+00:00' AIRFLOW_CTX_TRY_NUMBER='2' AIRFLOW_CTX_DAG_RUN_ID='manual__2025-02-02T19:35:41.450846+00:00'
[2025-02-02T19:41:04.470+0000] {taskinstance.py:731} INFO - ::endgroup::
[2025-02-02T19:41:05.224+0000] {logging_mixin.py:190} INFO - Skipping row with NULL time_position: {'icao24': 'e80218', 'callsign': 'LAN407  ', 'origin_country': 'Chile', 'time_position': None, 'last_contact': 1738524944, 'longitude': None, 'latitude': None, 'baro_altitude': None, 'on_ground': False, 'velocity': 257.83, 'true_track': 219.09, 'vertical_rate': 0, 'sensors': None, 'geo_altitude': None, 'squawk': None, 'spi': False, 'position_source': 0, 'category': 0}
[2025-02-02T19:41:05.246+0000] {logging_mixin.py:190} INFO - Skipping row with NULL time_position: {'icao24': 'a09dc5', 'callsign': '', 'origin_country': 'United States', 'time_position': None, 'last_contact': 1738524863, 'longitude': None, 'latitude': None, 'baro_altitude': None, 'on_ground': False, 'velocity': 63.49, 'true_track': 85.35, 'vertical_rate': 1.95, 'sensors': None, 'geo_altitude': None, 'squawk': None, 'spi': False, 'position_source': 0, 'category': 0}
[2025-02-02T19:41:05.318+0000] {logging_mixin.py:190} INFO - Skipping row with NULL time_position: {'icao24': 'e0b244', 'callsign': 'ARG1246 ', 'origin_country': 'Argentina', 'time_position': None, 'last_contact': 1738524945, 'longitude': None, 'latitude': None, 'baro_altitude': None, 'on_ground': False, 'velocity': 230.91, 'true_track': 36.03, 'vertical_rate': 0, 'sensors': None, 'geo_altitude': None, 'squawk': None, 'spi': False, 'position_source': 0, 'category': 0}
[2025-02-02T19:41:05.346+0000] {logging_mixin.py:190} INFO - Skipping row with NULL time_position: {'icao24': '471f9e', 'callsign': 'WMT3MM  ', 'origin_country': 'Hungary', 'time_position': None, 'last_contact': 1738524946, 'longitude': None, 'latitude': None, 'baro_altitude': None, 'on_ground': False, 'velocity': 81.8, 'true_track': 0.36, 'vertical_rate': 13, 'sensors': None, 'geo_altitude': None, 'squawk': None, 'spi': False, 'position_source': 0, 'category': 0}
[2025-02-02T19:41:05.388+0000] {logging_mixin.py:190} INFO - Skipping row with NULL time_position: {'icao24': 'a951d1', 'callsign': 'N7WA    ', 'origin_country': 'United States', 'time_position': None, 'last_contact': 1738524927, 'longitude': None, 'latitude': None, 'baro_altitude': None, 'on_ground': False, 'velocity': 77.76, 'true_track': 22.15, 'vertical_rate': 0.33, 'sensors': None, 'geo_altitude': None, 'squawk': None, 'spi': False, 'position_source': 0, 'category': 0}
[2025-02-02T19:41:05.399+0000] {logging_mixin.py:190} INFO - Doublon ignoré: ['0d0b67', '', 'Mexico', 1738524945, 1738524945, -99.2338, 19.4788, 3444.24, False, 128.63, 179.08, -7.48, None, 3665.22, None, False, 0, 0] - Error: Constraint Error: Duplicate key "callsign: , time_position: 1738524945, last_contact: 1738524945" violates primary key constraint. If this is an unexpected constraint violation please double check with the known index limitations section in our documentation (https://duckdb.org/docs/sql/indexes).
[2025-02-02T19:41:05.505+0000] {logging_mixin.py:190} INFO - Skipping row with NULL time_position: {'icao24': 'e4803d', 'callsign': 'TAM8143 ', 'origin_country': 'Brazil', 'time_position': None, 'last_contact': 1738524945, 'longitude': None, 'latitude': None, 'baro_altitude': None, 'on_ground': False, 'velocity': 224.42, 'true_track': 39.42, 'vertical_rate': -0.33, 'sensors': None, 'geo_altitude': None, 'squawk': None, 'spi': False, 'position_source': 0, 'category': 0}
[2025-02-02T19:41:06.757+0000] {logging_mixin.py:190} INFO - Skipping row with NULL time_position: {'icao24': 'e073cf', 'callsign': 'ARG1229 ', 'origin_country': 'Argentina', 'time_position': None, 'last_contact': 1738524945, 'longitude': None, 'latitude': None, 'baro_altitude': None, 'on_ground': False, 'velocity': 238.01, 'true_track': 221.41, 'vertical_rate': 0, 'sensors': None, 'geo_altitude': None, 'squawk': None, 'spi': False, 'position_source': 0, 'category': 0}
[2025-02-02T19:41:06.856+0000] {logging_mixin.py:190} INFO - Doublon ignoré: ['e0268f', '', 'Argentina', 1738524945, 1738524945, -58.4128, -34.5593, None, True, 3.86, 135, None, None, None, None, False, 0, 0] - Error: Constraint Error: Duplicate key "callsign: , time_position: 1738524945, last_contact: 1738524945" violates primary key constraint. If this is an unexpected constraint violation please double check with the known index limitations section in our documentation (https://duckdb.org/docs/sql/indexes).
[2025-02-02T19:41:06.903+0000] {taskinstance.py:3301} ERROR - Task failed with exception
Traceback (most recent call last):
  File "/opt/airflow/dags/zdag.py", line 105, in load_data_into_duckdb
    conn.execute(f"INSERT INTO openskynetwork_brute VALUES ({placeholders})", tuple(values))
duckdb.duckdb.ConstraintException: Constraint Error: Duplicate key "callsign: , time_position: 1738524945, last_contact: 1738524945" violates primary key constraint. If this is an unexpected constraint violation please double check with the known index limitations section in our documentation (https://duckdb.org/docs/sql/indexes).

During handling of the above exception, another exception occurred:

Traceback (most recent call last):
  File "/opt/airflow/dags/zdag.py", line 108, in load_data_into_duckdb
    conn.rollback() #annuler l'insertion en doublon
    ^^^^^^^^^^^^^^^
duckdb.duckdb.TransactionException: TransactionContext Error: cannot rollback - no transaction is active

During handling of the above exception, another exception occurred:

Traceback (most recent call last):
  File "/home/airflow/.local/lib/python3.12/site-packages/airflow/models/taskinstance.py", line 767, in _execute_task
    result = _execute_callable(context=context, **execute_callable_kwargs)
             ^^^^^^^^^^^^^^^^^^^^^^^^^^^^^^^^^^^^^^^^^^^^^^^^^^^^^^^^^^^^^
  File "/home/airflow/.local/lib/python3.12/site-packages/airflow/models/taskinstance.py", line 733, in _execute_callable
    return ExecutionCallableRunner(
           ^^^^^^^^^^^^^^^^^^^^^^^^
  File "/home/airflow/.local/lib/python3.12/site-packages/airflow/utils/operator_helpers.py", line 252, in run
    return self.func(*args, **kwargs)
           ^^^^^^^^^^^^^^^^^^^^^^^^^^
  File "/home/airflow/.local/lib/python3.12/site-packages/airflow/models/baseoperator.py", line 406, in wrapper
    return func(self, *args, **kwargs)
           ^^^^^^^^^^^^^^^^^^^^^^^^^^^
  File "/home/airflow/.local/lib/python3.12/site-packages/airflow/decorators/base.py", line 266, in execute
    return_value = super().execute(context)
                   ^^^^^^^^^^^^^^^^^^^^^^^^
  File "/home/airflow/.local/lib/python3.12/site-packages/airflow/models/baseoperator.py", line 406, in wrapper
    return func(self, *args, **kwargs)
           ^^^^^^^^^^^^^^^^^^^^^^^^^^^
  File "/home/airflow/.local/lib/python3.12/site-packages/airflow/operators/python.py", line 238, in execute
    return_value = self.execute_callable()
                   ^^^^^^^^^^^^^^^^^^^^^^^
  File "/home/airflow/.local/lib/python3.12/site-packages/airflow/operators/python.py", line 256, in execute_callable
    return runner.run(*self.op_args, **self.op_kwargs)
           ^^^^^^^^^^^^^^^^^^^^^^^^^^^^^^^^^^^^^^^^^^^
  File "/home/airflow/.local/lib/python3.12/site-packages/airflow/utils/operator_helpers.py", line 252, in run
    return self.func(*args, **kwargs)
           ^^^^^^^^^^^^^^^^^^^^^^^^^^
  File "/opt/airflow/dags/zdag.py", line 118, in load_data_into_duckdb
    conn.rollback()
duckdb.duckdb.TransactionException: TransactionContext Error: cannot rollback - no transaction is active
[2025-02-02T19:41:06.929+0000] {taskinstance.py:1225} INFO - Marking task as FAILED. dag_id=flights_pipeline, task_id=load_data_into_duckdb, run_id=manual__2025-02-02T19:35:41.450846+00:00, execution_date=20250202T193541, start_date=20250202T194104, end_date=20250202T194106
[2025-02-02T19:41:06.943+0000] {taskinstance.py:340} INFO - ::group::Post task execution logs
[2025-02-02T19:41:06.943+0000] {standard_task_runner.py:124} ERROR - Failed to execute job 58 for task load_data_into_duckdb (TransactionContext Error: cannot rollback - no transaction is active; 2132)
Traceback (most recent call last):
  File "/opt/airflow/dags/zdag.py", line 105, in load_data_into_duckdb
    conn.execute(f"INSERT INTO openskynetwork_brute VALUES ({placeholders})", tuple(values))
duckdb.duckdb.ConstraintException: Constraint Error: Duplicate key "callsign: , time_position: 1738524945, last_contact: 1738524945" violates primary key constraint. If this is an unexpected constraint violation please double check with the known index limitations section in our documentation (https://duckdb.org/docs/sql/indexes).

During handling of the above exception, another exception occurred:

Traceback (most recent call last):
  File "/opt/airflow/dags/zdag.py", line 108, in load_data_into_duckdb
    conn.rollback() #annuler l'insertion en doublon
    ^^^^^^^^^^^^^^^
duckdb.duckdb.TransactionException: TransactionContext Error: cannot rollback - no transaction is active

During handling of the above exception, another exception occurred:

Traceback (most recent call last):
  File "/home/airflow/.local/lib/python3.12/site-packages/airflow/task/task_runner/standard_task_runner.py", line 117, in _start_by_fork
    ret = args.func(args, dag=self.dag)
          ^^^^^^^^^^^^^^^^^^^^^^^^^^^^^
  File "/home/airflow/.local/lib/python3.12/site-packages/airflow/cli/cli_config.py", line 49, in command
    return func(*args, **kwargs)
           ^^^^^^^^^^^^^^^^^^^^^
  File "/home/airflow/.local/lib/python3.12/site-packages/airflow/utils/cli.py", line 115, in wrapper
    return f(*args, **kwargs)
           ^^^^^^^^^^^^^^^^^^
  File "/home/airflow/.local/lib/python3.12/site-packages/airflow/cli/commands/task_command.py", line 483, in task_run
    task_return_code = _run_task_by_selected_method(args, _dag, ti)
                       ^^^^^^^^^^^^^^^^^^^^^^^^^^^^^^^^^^^^^^^^^^^^
  File "/home/airflow/.local/lib/python3.12/site-packages/airflow/cli/commands/task_command.py", line 256, in _run_task_by_selected_method
    return _run_raw_task(args, ti)
           ^^^^^^^^^^^^^^^^^^^^^^^
  File "/home/airflow/.local/lib/python3.12/site-packages/airflow/cli/commands/task_command.py", line 341, in _run_raw_task
    return ti._run_raw_task(
           ^^^^^^^^^^^^^^^^^
  File "/home/airflow/.local/lib/python3.12/site-packages/airflow/utils/session.py", line 97, in wrapper
    return func(*args, session=session, **kwargs)
           ^^^^^^^^^^^^^^^^^^^^^^^^^^^^^^^^^^^^^^
  File "/home/airflow/.local/lib/python3.12/site-packages/airflow/models/taskinstance.py", line 2995, in _run_raw_task
    return _run_raw_task(
           ^^^^^^^^^^^^^^
  File "/home/airflow/.local/lib/python3.12/site-packages/airflow/models/taskinstance.py", line 273, in _run_raw_task
    TaskInstance._execute_task_with_callbacks(
  File "/home/airflow/.local/lib/python3.12/site-packages/airflow/models/taskinstance.py", line 3149, in _execute_task_with_callbacks
    result = self._execute_task(context, task_orig)
             ^^^^^^^^^^^^^^^^^^^^^^^^^^^^^^^^^^^^^^
  File "/home/airflow/.local/lib/python3.12/site-packages/airflow/models/taskinstance.py", line 3173, in _execute_task
    return _execute_task(self, context, task_orig)
           ^^^^^^^^^^^^^^^^^^^^^^^^^^^^^^^^^^^^^^^
  File "/home/airflow/.local/lib/python3.12/site-packages/airflow/models/taskinstance.py", line 767, in _execute_task
    result = _execute_callable(context=context, **execute_callable_kwargs)
             ^^^^^^^^^^^^^^^^^^^^^^^^^^^^^^^^^^^^^^^^^^^^^^^^^^^^^^^^^^^^^
  File "/home/airflow/.local/lib/python3.12/site-packages/airflow/models/taskinstance.py", line 733, in _execute_callable
    return ExecutionCallableRunner(
           ^^^^^^^^^^^^^^^^^^^^^^^^
  File "/home/airflow/.local/lib/python3.12/site-packages/airflow/utils/operator_helpers.py", line 252, in run
    return self.func(*args, **kwargs)
           ^^^^^^^^^^^^^^^^^^^^^^^^^^
  File "/home/airflow/.local/lib/python3.12/site-packages/airflow/models/baseoperator.py", line 406, in wrapper
    return func(self, *args, **kwargs)
           ^^^^^^^^^^^^^^^^^^^^^^^^^^^
  File "/home/airflow/.local/lib/python3.12/site-packages/airflow/decorators/base.py", line 266, in execute
    return_value = super().execute(context)
                   ^^^^^^^^^^^^^^^^^^^^^^^^
  File "/home/airflow/.local/lib/python3.12/site-packages/airflow/models/baseoperator.py", line 406, in wrapper
    return func(self, *args, **kwargs)
           ^^^^^^^^^^^^^^^^^^^^^^^^^^^
  File "/home/airflow/.local/lib/python3.12/site-packages/airflow/operators/python.py", line 238, in execute
    return_value = self.execute_callable()
                   ^^^^^^^^^^^^^^^^^^^^^^^
  File "/home/airflow/.local/lib/python3.12/site-packages/airflow/operators/python.py", line 256, in execute_callable
    return runner.run(*self.op_args, **self.op_kwargs)
           ^^^^^^^^^^^^^^^^^^^^^^^^^^^^^^^^^^^^^^^^^^^
  File "/home/airflow/.local/lib/python3.12/site-packages/airflow/utils/operator_helpers.py", line 252, in run
    return self.func(*args, **kwargs)
           ^^^^^^^^^^^^^^^^^^^^^^^^^^
  File "/opt/airflow/dags/zdag.py", line 118, in load_data_into_duckdb
    conn.rollback()
duckdb.duckdb.TransactionException: TransactionContext Error: cannot rollback - no transaction is active
[2025-02-02T19:41:06.974+0000] {local_task_job_runner.py:261} INFO - Task exited with return code 1
[2025-02-02T19:41:06.986+0000] {taskinstance.py:3891} INFO - 0 downstream tasks scheduled from follow-on schedule check
[2025-02-02T19:41:06.991+0000] {local_task_job_runner.py:240} INFO - ::endgroup::
